<?xml version="1.0" ?>
<!-- =================================================================================== -->
<!-- |    This document was autogenerated by xacro from my_robot_description/urdf/dual_dummy_arm_shadow.urdf.xacro | -->
<!-- |    EDITING THIS FILE BY HAND IS NOT RECOMMENDED                                 | -->
<!-- =================================================================================== -->
<robot name="dual_ur5">
  <!-- use z_offset = -1 in isaac gym -->
  <!-- Base Link -->
  <link name="ra_base">
    <inertial>
      <mass value="0.001"/>
      <origin xyz="0 0 0"/>
      <inertia ixx="0.0001" ixy="0.0" ixz="0.0" iyy="0.0001" iyz="0.0" izz="0.0001"/>
    </inertial>
  </link>
  <!-- Translation X -->
  <link name="ra_TransXB">
    <inertial>
      <mass value="0.001"/>
      <origin xyz="0 0 0"/>
      <inertia ixx="0.0001" ixy="0.0" ixz="0.0" iyy="0.0001" iyz="0.0" izz="0.0001"/>
    </inertial>
  </link>
  <joint name="ra_TransXJ" type="prismatic">
    <parent link="ra_base"/>
    <child link="ra_TransXB"/>
    <axis xyz="1 0 0"/>
    <limit effort="10000000" lower="-1" upper="1" velocity="1000"/>
  </joint>
  <!-- Translation Y -->
  <link name="ra_TransYB">
    <inertial>
      <mass value="0.001"/>
      <origin xyz="0 0 0"/>
      <inertia ixx="0.0001" ixy="0.0" ixz="0.0" iyy="0.0001" iyz="0.0" izz="0.0001"/>
    </inertial>
  </link>
  <joint name="ra_TransYJ" type="prismatic">
    <parent link="ra_TransXB"/>
    <child link="ra_TransYB"/>
    <axis xyz="0 1 0"/>
    <limit effort="10000000" lower="-1" upper="1" velocity="1000"/>
  </joint>
  <!-- Translation Z -->
  <link name="ra_TransZB">
    <inertial>
      <mass value="0.001"/>
      <origin xyz="0 0 0"/>
      <inertia ixx="0.0001" ixy="0.0" ixz="0.0" iyy="0.0001" iyz="0.0" izz="0.0001"/>
    </inertial>
  </link>
  <joint name="ra_TransZJ" type="prismatic">
    <parent link="ra_TransYB"/>
    <child link="ra_TransZB"/>
    <origin xyz="0 0 0"/>
    <axis xyz="0 0 1"/>
    <limit effort="10000000" lower="-1" upper="1" velocity="1000"/>
  </joint>
  <!-- Rotation X -->
  <link name="ra_RotXB">
    <inertial>
      <mass value="0.001"/>
      <origin xyz="0 0 0"/>
      <inertia ixx="0.0001" ixy="0.0" ixz="0.0" iyy="0.0001" iyz="0.0" izz="0.0001"/>
    </inertial>
  </link>
  <joint name="ra_RotXJ" type="revolute">
    <parent link="ra_TransZB"/>
    <child link="ra_RotXB"/>
    <axis xyz="1 0 0"/>
    <limit effort="10000000" lower="-6.283" upper="6.283" velocity="1000"/>
  </joint>
  <!-- Rotation Y -->
  <link name="ra_RotYB">
    <inertial>
      <mass value="0.001"/>
      <origin xyz="0 0 0"/>
      <inertia ixx="0.0001" ixy="0.0" ixz="0.0" iyy="0.0001" iyz="0.0" izz="0.0001"/>
    </inertial>
  </link>
  <joint name="ra_RotYJ" type="revolute">
    <parent link="ra_RotXB"/>
    <child link="ra_RotYB"/>
    <axis xyz="0 1 0"/>
    <limit effort="10000000" lower="-6.283" upper="6.283" velocity="1000"/>
  </joint>
  <!-- Rotation Z -->
  <link name="ra_RotZB">
    <inertial>
      <mass value="0.001"/>
      <origin xyz="0 0 0"/>
      <inertia ixx="0.0001" ixy="0.0" ixz="0.0" iyy="0.0001" iyz="0.0" izz="0.0001"/>
    </inertial>
  </link>
  <joint name="ra_RotZJ" type="revolute">
    <parent link="ra_RotYB"/>
    <child link="ra_RotZB"/>
    <axis xyz="0 0 1"/>
    <limit effort="10000000" lower="-6.283" upper="6.283" velocity="1000"/>
  </joint>
  <!-- use z_offset = -1 in isaac gym -->
  <!-- Base Link -->
  <link name="la_base">
    <inertial>
      <mass value="0.001"/>
      <origin xyz="0 0 0"/>
      <inertia ixx="0.0001" ixy="0.0" ixz="0.0" iyy="0.0001" iyz="0.0" izz="0.0001"/>
    </inertial>
  </link>
  <!-- Translation X -->
  <link name="la_TransXB">
    <inertial>
      <mass value="0.001"/>
      <origin xyz="0 0 0"/>
      <inertia ixx="0.0001" ixy="0.0" ixz="0.0" iyy="0.0001" iyz="0.0" izz="0.0001"/>
    </inertial>
  </link>
  <joint name="la_TransXJ" type="prismatic">
    <parent link="la_base"/>
    <child link="la_TransXB"/>
    <axis xyz="1 0 0"/>
    <limit effort="10000000" lower="-1" upper="1" velocity="1000"/>
  </joint>
  <!-- Translation Y -->
  <link name="la_TransYB">
    <inertial>
      <mass value="0.001"/>
      <origin xyz="0 0 0"/>
      <inertia ixx="0.0001" ixy="0.0" ixz="0.0" iyy="0.0001" iyz="0.0" izz="0.0001"/>
    </inertial>
  </link>
  <joint name="la_TransYJ" type="prismatic">
    <parent link="la_TransXB"/>
    <child link="la_TransYB"/>
    <axis xyz="0 1 0"/>
    <limit effort="10000000" lower="-1" upper="1" velocity="1000"/>
  </joint>
  <!-- Translation Z -->
  <link name="la_TransZB">
    <inertial>
      <mass value="0.001"/>
      <origin xyz="0 0 0"/>
      <inertia ixx="0.0001" ixy="0.0" ixz="0.0" iyy="0.0001" iyz="0.0" izz="0.0001"/>
    </inertial>
  </link>
  <joint name="la_TransZJ" type="prismatic">
    <parent link="la_TransYB"/>
    <child link="la_TransZB"/>
    <origin xyz="0 0 0"/>
    <axis xyz="0 0 1"/>
    <limit effort="10000000" lower="-1" upper="1" velocity="1000"/>
  </joint>
  <!-- Rotation X -->
  <link name="la_RotXB">
    <inertial>
      <mass value="0.001"/>
      <origin xyz="0 0 0"/>
      <inertia ixx="0.0001" ixy="0.0" ixz="0.0" iyy="0.0001" iyz="0.0" izz="0.0001"/>
    </inertial>
  </link>
  <joint name="la_RotXJ" type="revolute">
    <parent link="la_TransZB"/>
    <child link="la_RotXB"/>
    <axis xyz="1 0 0"/>
    <limit effort="10000000" lower="-6.283" upper="6.283" velocity="1000"/>
  </joint>
  <!-- Rotation Y -->
  <link name="la_RotYB">
    <inertial>
      <mass value="0.001"/>
      <origin xyz="0 0 0"/>
      <inertia ixx="0.0001" ixy="0.0" ixz="0.0" iyy="0.0001" iyz="0.0" izz="0.0001"/>
    </inertial>
  </link>
  <joint name="la_RotYJ" type="revolute">
    <parent link="la_RotXB"/>
    <child link="la_RotYB"/>
    <axis xyz="0 1 0"/>
    <limit effort="10000000" lower="-6.283" upper="6.283" velocity="1000"/>
  </joint>
  <!-- Rotation Z -->
  <link name="la_RotZB">
    <inertial>
      <mass value="0.001"/>
      <origin xyz="0 0 0"/>
      <inertia ixx="0.0001" ixy="0.0" ixz="0.0" iyy="0.0001" iyz="0.0" izz="0.0001"/>
    </inertial>
  </link>
  <joint name="la_RotZJ" type="revolute">
    <parent link="la_RotYB"/>
    <child link="la_RotZB"/>
    <axis xyz="0 0 1"/>
    <limit effort="10000000" lower="-6.283" upper="6.283" velocity="1000"/>
  </joint>
  <link name="rh_palm">
    <visual name="palm">
      <origin rpy="0.2100458392356129 0.08313278223257159 1.5503210950325148" xyz="0.005374445170477271 -0.0022442906559082794 0.03201294312033412"/>
      <geometry>
        <mesh filename="stl/right_palm.stl"/>
      </geometry>
      <material name="white"/>
    </visual>
  </link>
  <link name="rh_ffknuckle">
    <visual name="f_knuckle">
      <origin rpy="0.4761390295154802 0.007276744315003247 -0.01128884895567703" xyz="-8.015943942283821e-06 0.00028383334511582203 0.0003141144870240873"/>
      <geometry>
        <mesh filename="stl/f_knuckle.stl"/>
      </geometry>
      <material name="white"/>
    </visual>
  </link>
  <joint name="rh_FFJ4" type="revolute">
    <parent link="rh_palm"/>
    <child link="rh_ffknuckle"/>
    <origin rpy="0.0 0.0 0.0" xyz="0.033 0.0 0.095"/>
    <axis xyz="0.0 -1.0 0.0"/>
    <limit effort="100" lower="-0.349066" upper="0.349066" velocity="100"/>
  </joint>
  <link name="rh_ffproximal">
    <visual name="f_proximal">
      <origin rpy="-7.135757573614219e-06 0.01189393423812235 1.5705980355726104" xyz="1.2104673000657597e-06 9.76175282387983e-06 0.022880653343431333"/>
      <geometry>
        <mesh filename="stl/f_proximal.stl"/>
      </geometry>
      <material name="white"/>
    </visual>
  </link>
  <joint name="rh_FFJ3" type="revolute">
    <parent link="rh_ffknuckle"/>
    <child link="rh_ffproximal"/>
    <origin rpy="0.0 0.0 0.0" xyz="0.0 0.0 0.0"/>
    <axis xyz="1.0 0.0 0.0"/>
    <limit effort="100" lower="-0.261799" upper="1.5708" velocity="100"/>
  </joint>
  <link name="rh_ffmiddle">
    <visual name="f_middle">
      <origin rpy="-1.5154077996843905e-05 -0.00025673504362555555 1.5707963267948966" xyz="-2.7197407046965675e-06 -3.219283283025054e-05 0.011511409944870538"/>
      <geometry>
        <mesh filename="stl/f_middle.stl"/>
      </geometry>
      <material name="white"/>
    </visual>
  </link>
  <joint name="rh_FFJ2" type="revolute">
    <parent link="rh_ffproximal"/>
    <child link="rh_ffmiddle"/>
    <origin rpy="0.0 0.0 0.0" xyz="0.0 0.0 0.045"/>
    <axis xyz="1.0 0.0 0.0"/>
    <limit effort="100" lower="0.0" upper="1.5708" velocity="100"/>
  </joint>
  <link name="rh_ffdistal">
    <visual name="f_distal_pst">
      <origin rpy="1.9593220200595154e-05 0.002689843516656243 1.582276007411751" xyz="-2.398434946392576e-05 0.00042073257364413626 0.017646475317320408"/>
      <geometry>
        <mesh filename="stl/f_distal_pst.stl"/>
      </geometry>
      <material name="white"/>
    </visual>
  </link>
  <joint name="rh_FFJ1" type="revolute">
    <parent link="rh_ffmiddle"/>
    <child link="rh_ffdistal"/>
    <origin rpy="0.0 0.0 0.0" xyz="0.0 0.0 0.025"/>
    <axis xyz="1.0 0.0 0.0"/>
    <limit effort="100" lower="0.0" upper="1.5708" velocity="100"/>
  </joint>
  <link name="rh_mfknuckle">
    <visual name="f_knuckle">
      <origin rpy="0.4761390295154802 0.007276744315003247 -0.01128884895567703" xyz="-8.015943942283821e-06 0.00028383334511582203 0.0003141144870240873"/>
      <geometry>
        <mesh filename="stl/f_knuckle.stl"/>
      </geometry>
      <material name="white"/>
    </visual>
  </link>
  <joint name="rh_MFJ4" type="revolute">
    <parent link="rh_palm"/>
    <child link="rh_mfknuckle"/>
    <origin rpy="0.0 0.0 0.0" xyz="0.011 0.0 0.099"/>
    <axis xyz="0.0 -1.0 0.0"/>
    <limit effort="100" lower="-0.349066" upper="0.349066" velocity="100"/>
  </joint>
  <link name="rh_mfproximal">
    <visual name="f_proximal">
      <origin rpy="-7.135757573614219e-06 0.01189393423812235 1.5705980355726104" xyz="1.2104673000657597e-06 9.76175282387983e-06 0.022880653343431333"/>
      <geometry>
        <mesh filename="stl/f_proximal.stl"/>
      </geometry>
      <material name="white"/>
    </visual>
  </link>
  <joint name="rh_MFJ3" type="revolute">
    <parent link="rh_mfknuckle"/>
    <child link="rh_mfproximal"/>
    <origin rpy="0.0 0.0 0.0" xyz="0.0 0.0 0.0"/>
    <axis xyz="1.0 0.0 0.0"/>
    <limit effort="100" lower="-0.261799" upper="1.5708" velocity="100"/>
  </joint>
  <link name="rh_mfmiddle">
    <visual name="f_middle">
      <origin rpy="-1.5154077996843905e-05 -0.00025673504362555555 1.5707963267948966" xyz="-2.7197407046965675e-06 -3.219283283025054e-05 0.011511409944870538"/>
      <geometry>
        <mesh filename="stl/f_middle.stl"/>
      </geometry>
      <material name="white"/>
    </visual>
  </link>
  <joint name="rh_MFJ2" type="revolute">
    <parent link="rh_mfproximal"/>
    <child link="rh_mfmiddle"/>
    <origin rpy="0.0 0.0 0.0" xyz="0.0 0.0 0.045"/>
    <axis xyz="1.0 0.0 0.0"/>
    <limit effort="100" lower="0.0" upper="1.5708" velocity="100"/>
  </joint>
  <link name="rh_mfdistal">
    <visual name="f_distal_pst">
      <origin rpy="1.9593220200595154e-05 0.002689843516656243 1.582276007411751" xyz="-2.398434946392576e-05 0.00042073257364413626 0.017646475317320408"/>
      <geometry>
        <mesh filename="stl/f_distal_pst.stl"/>
      </geometry>
      <material name="white"/>
    </visual>
  </link>
  <joint name="rh_MFJ1" type="revolute">
    <parent link="rh_mfmiddle"/>
    <child link="rh_mfdistal"/>
    <origin rpy="0.0 0.0 0.0" xyz="0.0 0.0 0.025"/>
    <axis xyz="1.0 0.0 0.0"/>
    <limit effort="100" lower="0.0" upper="1.5708" velocity="100"/>
  </joint>
  <link name="rh_rfknuckle">
    <visual name="f_knuckle">
      <origin rpy="0.4761390295154802 0.007276744315003247 -0.01128884895567703" xyz="-8.015943942283821e-06 0.00028383334511582203 0.0003141144870240873"/>
      <geometry>
        <mesh filename="stl/f_knuckle.stl"/>
      </geometry>
      <material name="white"/>
    </visual>
  </link>
  <joint name="rh_RFJ4" type="revolute">
    <parent link="rh_palm"/>
    <child link="rh_rfknuckle"/>
    <origin rpy="0.0 0.0 0.0" xyz="-0.011 0.0 0.095"/>
    <axis xyz="0.0 1.0 0.0"/>
    <limit effort="100" lower="-0.349066" upper="0.349066" velocity="100"/>
  </joint>
  <link name="rh_rfproximal">
    <visual name="f_proximal">
      <origin rpy="-7.135757573614219e-06 0.01189393423812235 1.5705980355726104" xyz="1.2104673000657597e-06 9.76175282387983e-06 0.022880653343431333"/>
      <geometry>
        <mesh filename="stl/f_proximal.stl"/>
      </geometry>
      <material name="white"/>
    </visual>
  </link>
  <joint name="rh_RFJ3" type="revolute">
    <parent link="rh_rfknuckle"/>
    <child link="rh_rfproximal"/>
    <origin rpy="0.0 0.0 0.0" xyz="0.0 0.0 0.0"/>
    <axis xyz="1.0 0.0 0.0"/>
    <limit effort="100" lower="-0.261799" upper="1.5708" velocity="100"/>
  </joint>
  <link name="rh_rfmiddle">
    <visual name="f_middle">
      <origin rpy="-1.5154077996843905e-05 -0.00025673504362555555 1.5707963267948966" xyz="-2.7197407046965675e-06 -3.219283283025054e-05 0.011511409944870538"/>
      <geometry>
        <mesh filename="stl/f_middle.stl"/>
      </geometry>
      <material name="white"/>
    </visual>
  </link>
  <joint name="rh_RFJ2" type="revolute">
    <parent link="rh_rfproximal"/>
    <child link="rh_rfmiddle"/>
    <origin rpy="0.0 0.0 0.0" xyz="0.0 0.0 0.045"/>
    <axis xyz="1.0 0.0 0.0"/>
    <limit effort="100" lower="0.0" upper="1.5708" velocity="100"/>
  </joint>
  <link name="rh_rfdistal">
    <visual name="f_distal_pst">
      <origin rpy="1.9593220200595154e-05 0.002689843516656243 1.582276007411751" xyz="-2.398434946392576e-05 0.00042073257364413626 0.017646475317320408"/>
      <geometry>
        <mesh filename="stl/f_distal_pst.stl"/>
      </geometry>
      <material name="white"/>
    </visual>
  </link>
  <joint name="rh_RFJ1" type="revolute">
    <parent link="rh_rfmiddle"/>
    <child link="rh_rfdistal"/>
    <origin rpy="0.0 0.0 0.0" xyz="0.0 0.0 0.025"/>
    <axis xyz="1.0 0.0 0.0"/>
    <limit effort="100" lower="0.0" upper="1.5708" velocity="100"/>
  </joint>
  <link name="rh_lfmetacarpal">
    <visual name="lf_metacarpal">
      <origin rpy="-0.8420695670279069 0.04469723682216371 1.565424596377065" xyz="-0.01889428  0.00066234  0.03130367"/>
      <geometry>
        <mesh filename="stl/right_lf_metacarpal.stl"/>
      </geometry>
      <material name="white"/>
    </visual>
  </link>
  <joint name="rh_LFJ5" type="revolute">
    <parent link="rh_palm"/>
    <child link="rh_lfmetacarpal"/>
    <origin rpy="0 0.6108649061631908 0" xyz="-0.033 0.0 0.02071"/>
    <axis xyz="0 0 1"/>
    <!-- <origin xyz="-0.033 0.0 0.02071" rpy="0.0 0.0 0.0"/>
      <axis xyz="0.5735761643640092 0.0 0.819152234736298"/> -->
    <limit effort="100" lower="0.0" upper="0.785398" velocity="100"/>
  </joint>
  <link name="rh_lfknuckle">
    <visual name="f_knuckle">
      <origin rpy="0.4761390295154802 0.007276744315003247 -0.01128884895567703" xyz="-8.015943942283821e-06 0.00028383334511582203 0.0003141144870240873"/>
      <geometry>
        <mesh filename="stl/f_knuckle.stl"/>
      </geometry>
      <material name="white"/>
    </visual>
  </link>
  <joint name="rh_LFJ4" type="revolute">
    <parent link="rh_lfmetacarpal"/>
    <child link="rh_lfknuckle"/>
    <!-- <origin xyz="0.0 0.0 0.06579" rpy="0.0 0.0 0.0"/> -->
    <origin rpy="0 -0.6108649061631908 0" xyz="-0.03773558 0. 0.05389203"/>
    <axis xyz="0.0 1.0 0.0"/>
    <limit effort="100" lower="-0.349066" upper="0.349066" velocity="100"/>
  </joint>
  <link name="rh_lfproximal">
    <visual name="f_proximal">
      <origin rpy="-7.135757573614219e-06 0.01189393423812235 1.5705980355726104" xyz="1.2104673000657597e-06 9.76175282387983e-06 0.022880653343431333"/>
      <geometry>
        <mesh filename="stl/f_proximal.stl"/>
      </geometry>
      <material name="white"/>
    </visual>
  </link>
  <joint name="rh_LFJ3" type="revolute">
    <parent link="rh_lfknuckle"/>
    <child link="rh_lfproximal"/>
    <origin rpy="0.0 0.0 0.0" xyz="0.0 0.0 0.0"/>
    <axis xyz="1.0 0.0 0.0"/>
    <limit effort="100" lower="-0.261799" upper="1.5708" velocity="100"/>
  </joint>
  <link name="rh_lfmiddle">
    <visual name="f_middle">
      <origin rpy="-1.5154077996843905e-05 -0.00025673504362555555 1.5707963267948966" xyz="-2.7197407046965675e-06 -3.219283283025054e-05 0.011511409944870538"/>
      <geometry>
        <mesh filename="stl/f_middle.stl"/>
      </geometry>
      <material name="white"/>
    </visual>
  </link>
  <joint name="rh_LFJ2" type="revolute">
    <parent link="rh_lfproximal"/>
    <child link="rh_lfmiddle"/>
    <origin rpy="0.0 0.0 0.0" xyz="0.0 0.0 0.045"/>
    <axis xyz="1.0 0.0 0.0"/>
    <limit effort="100" lower="0.0" upper="1.5708" velocity="100"/>
  </joint>
  <link name="rh_lfdistal">
    <visual name="f_distal_pst">
      <origin rpy="1.9593220200595154e-05 0.002689843516656243 1.582276007411751" xyz="-2.398434946392576e-05 0.00042073257364413626 0.017646475317320408"/>
      <geometry>
        <mesh filename="stl/f_distal_pst.stl"/>
      </geometry>
      <material name="white"/>
    </visual>
  </link>
  <joint name="rh_LFJ1" type="revolute">
    <parent link="rh_lfmiddle"/>
    <child link="rh_lfdistal"/>
    <origin rpy="0.0 0.0 0.0" xyz="0.0 0.0 0.025"/>
    <axis xyz="1.0 0.0 0.0"/>
    <limit effort="100" lower="0.0" upper="1.5708" velocity="100"/>
  </joint>
  <link name="rh_thbase"/>
  <joint name="rh_THJ5" type="revolute">
    <parent link="rh_palm"/>
    <child link="rh_thbase"/>
    <origin rpy="0.0 0.7853970066908715 0.0" xyz="0.034 -0.00858 0.029"/>
    <axis xyz="0.0 0.0 -1.0"/>
    <limit effort="100" lower="-1.0472" upper="1.0472" velocity="100"/>
  </joint>
  <link name="rh_thproximal">
    <visual name="th_proximal">
      <origin rpy="-4.186875454471058e-06 0.0010962409823094266 0.3847587823606159" xyz="-6.378894056540728e-06 -2.6031284627244637e-05 0.016715298411459745"/>
      <geometry>
        <mesh filename="stl/th_proximal.stl"/>
      </geometry>
      <material name="white"/>
    </visual>
  </link>
  <joint name="rh_THJ4" type="revolute">
    <parent link="rh_thbase"/>
    <child link="rh_thproximal"/>
    <origin rpy="0.0 0.0 0.0" xyz="0.0 0.0 0.0"/>
    <axis xyz="1.0 0.0 0.0"/>
    <limit effort="100" lower="0.0" upper="1.22173" velocity="100"/>
  </joint>
  <link name="rh_thhub"/>
  <joint name="rh_THJ3" type="revolute">
    <parent link="rh_thproximal"/>
    <child link="rh_thhub"/>
    <origin rpy="0.0 0.0 0.0" xyz="0.0 0.0 0.038"/>
    <axis xyz="1.0 0.0 0.0"/>
    <limit effort="100" lower="-0.20944" upper="0.20944" velocity="100"/>
  </joint>
  <link name="rh_thmiddle">
    <visual name="th_middle">
      <origin rpy="0.0 -0.0009035488116579948 0.0" xyz="7.479629857400793e-05 -4.506977852869377e-05 0.015348398308984388"/>
      <geometry>
        <mesh filename="stl/th_middle.stl"/>
      </geometry>
      <material name="white"/>
    </visual>
  </link>
  <joint name="rh_THJ2" type="revolute">
    <parent link="rh_thhub"/>
    <child link="rh_thmiddle"/>
    <origin rpy="0.0 0.0 0.0" xyz="0.0 0.0 0.0"/>
    <axis xyz="0.0 -1.0 0.0"/>
    <limit effort="100" lower="-0.698132" upper="0.698132" velocity="100"/>
  </joint>
  <link name="rh_thdistal">
    <visual name="th_distal_pst">
      <origin rpy="-0.0001073181947076323 0.003173495876248822 1.5706693697416252" xyz="-8.254509753145168e-07 0.000802518759472585 0.019553373143358997"/>
      <geometry>
        <mesh filename="stl/th_distal_pst.stl"/>
      </geometry>
      <material name="white"/>
    </visual>
  </link>
  <joint name="rh_THJ1" type="revolute">
    <parent link="rh_thmiddle"/>
    <child link="rh_thdistal"/>
    <origin rpy="0.0 0.0 -1.5707963267948963" xyz="0.0 0.0 0.032"/>
    <axis xyz="1.0 0.0 0.0"/>
    <limit effort="100" lower="-0.261799" upper="1.5708" velocity="100"/>
  </joint>
  <material name="white">
    <color rgba="1 1 1 1"/>
  </material>
  <link name="lh_palm">
    <visual name="palm">
      <origin rpy="-0.2100458360522472 0.08313278287794423 1.5912715584960464" xyz="-0.005374445159140238 -0.0022442906529939566 0.0320129431647506"/>
      <geometry>
        <mesh filename="stl/left_palm.stl"/>
      </geometry>
      <material name="white"/>
    </visual>
  </link>
  <link name="lh_ffknuckle">
    <visual name="f_knuckle">
      <origin rpy="0.4761390295154802 0.007276744315003247 -0.01128884895567703" xyz="-8.015943942283821e-06 0.00028383334511582203 0.0003141144870240873"/>
      <geometry>
        <mesh filename="stl/f_knuckle.stl"/>
      </geometry>
      <material name="white"/>
    </visual>
  </link>
  <joint name="lh_FFJ4" type="revolute">
    <parent link="lh_palm"/>
    <child link="lh_ffknuckle"/>
    <origin rpy="0.0 0.0 0.0" xyz="-0.033 0.0 0.095"/>
    <axis xyz="0.0 1.0 0.0"/>
    <limit effort="100" lower="-0.349066" upper="0.349066" velocity="100"/>
  </joint>
  <link name="lh_ffproximal">
    <visual name="f_proximal">
      <origin rpy="-7.135757573614219e-06 0.01189393423812235 1.5705980355726104" xyz="1.2104673000657597e-06 9.76175282387983e-06 0.022880653343431333"/>
      <geometry>
        <mesh filename="stl/f_proximal.stl"/>
      </geometry>
      <material name="white"/>
    </visual>
  </link>
  <joint name="lh_FFJ3" type="revolute">
    <parent link="lh_ffknuckle"/>
    <child link="lh_ffproximal"/>
    <origin rpy="0.0 0.0 0.0" xyz="0.0 0.0 0.0"/>
    <axis xyz="1.0 0.0 0.0"/>
    <limit effort="100" lower="-0.261799" upper="1.5708" velocity="100"/>
  </joint>
  <link name="lh_ffmiddle">
    <visual name="f_middle">
      <origin rpy="-1.5154077996843905e-05 -0.00025673504362555555 1.5707963267948966" xyz="-2.7197407046965675e-06 -3.219283283025054e-05 0.011511409944870538"/>
      <geometry>
        <mesh filename="stl/f_middle.stl"/>
      </geometry>
      <material name="white"/>
    </visual>
  </link>
  <joint name="lh_FFJ2" type="revolute">
    <parent link="lh_ffproximal"/>
    <child link="lh_ffmiddle"/>
    <origin rpy="0.0 0.0 0.0" xyz="0.0 0.0 0.045"/>
    <axis xyz="1.0 0.0 0.0"/>
    <limit effort="100" lower="0.0" upper="1.5708" velocity="100"/>
  </joint>
  <link name="lh_ffdistal">
    <visual name="f_distal_pst">
      <origin rpy="1.9593220200595154e-05 0.002689843516656243 1.582276007411751" xyz="-2.398434946392576e-05 0.00042073257364413626 0.017646475317320408"/>
      <geometry>
        <mesh filename="stl/f_distal_pst.stl"/>
      </geometry>
      <material name="white"/>
    </visual>
  </link>
  <joint name="lh_FFJ1" type="revolute">
    <parent link="lh_ffmiddle"/>
    <child link="lh_ffdistal"/>
    <origin rpy="0.0 0.0 0.0" xyz="0.0 0.0 0.025"/>
    <axis xyz="1.0 0.0 0.0"/>
    <limit effort="100" lower="0.0" upper="1.5708" velocity="100"/>
  </joint>
  <link name="lh_mfknuckle">
    <visual name="f_knuckle">
      <origin rpy="0.4761390295154802 0.007276744315003247 -0.01128884895567703" xyz="-8.015943942283821e-06 0.00028383334511582203 0.0003141144870240873"/>
      <geometry>
        <mesh filename="stl/f_knuckle.stl"/>
      </geometry>
      <material name="white"/>
    </visual>
  </link>
  <joint name="lh_MFJ4" type="revolute">
    <parent link="lh_palm"/>
    <child link="lh_mfknuckle"/>
    <origin rpy="0.0 0.0 0.0" xyz="-0.011 0.0 0.099"/>
    <axis xyz="0.0 1.0 0.0"/>
    <limit effort="100" lower="-0.349066" upper="0.349066" velocity="100"/>
  </joint>
  <link name="lh_mfproximal">
    <visual name="f_proximal">
      <origin rpy="-7.135757573614219e-06 0.01189393423812235 1.5705980355726104" xyz="1.2104673000657597e-06 9.76175282387983e-06 0.022880653343431333"/>
      <geometry>
        <mesh filename="stl/f_proximal.stl"/>
      </geometry>
      <material name="white"/>
    </visual>
  </link>
  <joint name="lh_MFJ3" type="revolute">
    <parent link="lh_mfknuckle"/>
    <child link="lh_mfproximal"/>
    <origin rpy="0.0 0.0 0.0" xyz="0.0 0.0 0.0"/>
    <axis xyz="1.0 0.0 0.0"/>
    <limit effort="100" lower="-0.261799" upper="1.5708" velocity="100"/>
  </joint>
  <link name="lh_mfmiddle">
    <visual name="f_middle">
      <origin rpy="-1.5154077996843905e-05 -0.00025673504362555555 1.5707963267948966" xyz="-2.7197407046965675e-06 -3.219283283025054e-05 0.011511409944870538"/>
      <geometry>
        <mesh filename="stl/f_middle.stl"/>
      </geometry>
      <material name="white"/>
    </visual>
  </link>
  <joint name="lh_MFJ2" type="revolute">
    <parent link="lh_mfproximal"/>
    <child link="lh_mfmiddle"/>
    <origin rpy="0.0 0.0 0.0" xyz="0.0 0.0 0.045"/>
    <axis xyz="1.0 0.0 0.0"/>
    <limit effort="100" lower="0.0" upper="1.5708" velocity="100"/>
  </joint>
  <link name="lh_mfdistal">
    <visual name="f_distal_pst">
      <origin rpy="1.9593220200595154e-05 0.002689843516656243 1.582276007411751" xyz="-2.398434946392576e-05 0.00042073257364413626 0.017646475317320408"/>
      <geometry>
        <mesh filename="stl/f_distal_pst.stl"/>
      </geometry>
      <material name="white"/>
    </visual>
  </link>
  <joint name="lh_MFJ1" type="revolute">
    <parent link="lh_mfmiddle"/>
    <child link="lh_mfdistal"/>
    <origin rpy="0.0 0.0 0.0" xyz="0.0 0.0 0.025"/>
    <axis xyz="1.0 0.0 0.0"/>
    <limit effort="100" lower="0.0" upper="1.5708" velocity="100"/>
  </joint>
  <link name="lh_rfknuckle">
    <visual name="f_knuckle">
      <origin rpy="0.4761390295154802 0.007276744315003247 -0.01128884895567703" xyz="-8.015943942283821e-06 0.00028383334511582203 0.0003141144870240873"/>
      <geometry>
        <mesh filename="stl/f_knuckle.stl"/>
      </geometry>
      <material name="white"/>
    </visual>
  </link>
  <joint name="lh_RFJ4" type="revolute">
    <parent link="lh_palm"/>
    <child link="lh_rfknuckle"/>
    <origin rpy="0.0 0.0 0.0" xyz="0.011 0.0 0.095"/>
    <axis xyz="0.0 -1.0 0.0"/>
    <limit effort="100" lower="-0.349066" upper="0.349066" velocity="100"/>
  </joint>
  <link name="lh_rfproximal">
    <visual name="f_proximal">
      <origin rpy="-7.135757573614219e-06 0.01189393423812235 1.5705980355726104" xyz="1.2104673000657597e-06 9.76175282387983e-06 0.022880653343431333"/>
      <geometry>
        <mesh filename="stl/f_proximal.stl"/>
      </geometry>
      <material name="white"/>
    </visual>
  </link>
  <joint name="lh_RFJ3" type="revolute">
    <parent link="lh_rfknuckle"/>
    <child link="lh_rfproximal"/>
    <origin rpy="0.0 0.0 0.0" xyz="0.0 0.0 0.0"/>
    <axis xyz="1.0 0.0 0.0"/>
    <limit effort="100" lower="-0.261799" upper="1.5708" velocity="100"/>
  </joint>
  <link name="lh_rfmiddle">
    <visual name="f_middle">
      <origin rpy="-1.5154077996843905e-05 -0.00025673504362555555 1.5707963267948966" xyz="-2.7197407046965675e-06 -3.219283283025054e-05 0.011511409944870538"/>
      <geometry>
        <mesh filename="stl/f_middle.stl"/>
      </geometry>
      <material name="white"/>
    </visual>
  </link>
  <joint name="lh_RFJ2" type="revolute">
    <parent link="lh_rfproximal"/>
    <child link="lh_rfmiddle"/>
    <origin rpy="0.0 0.0 0.0" xyz="0.0 0.0 0.045"/>
    <axis xyz="1.0 0.0 0.0"/>
    <limit effort="100" lower="0.0" upper="1.5708" velocity="100"/>
  </joint>
  <link name="lh_rfdistal">
    <visual name="f_distal_pst">
      <origin rpy="1.9593220200595154e-05 0.002689843516656243 1.582276007411751" xyz="-2.398434946392576e-05 0.00042073257364413626 0.017646475317320408"/>
      <geometry>
        <mesh filename="stl/f_distal_pst.stl"/>
      </geometry>
      <material name="white"/>
    </visual>
  </link>
  <joint name="lh_RFJ1" type="revolute">
    <parent link="lh_rfmiddle"/>
    <child link="lh_rfdistal"/>
    <origin rpy="0.0 0.0 0.0" xyz="0.0 0.0 0.025"/>
    <axis xyz="1.0 0.0 0.0"/>
    <limit effort="100" lower="0.0" upper="1.5708" velocity="100"/>
  </joint>
  <link name="lh_lfmetacarpal">
    <visual name="lf_metacarpal">
      <origin rpy="-2.3000784239220704 -0.020326401574026515 -1.6109676962386363" xyz="0.01889428 -0.00066234 -0.03130367"/>
      <!-- <origin xyz="-0.0024777484490041417 0.0006623357453732885 0.036479774502610314"
         rpy="0.23066278733853368 0.039690075483540976 1.5920475463254278"/> -->
      <geometry>
        <mesh filename="stl/left_lf_metacarpal.stl"/>
      </geometry>
      <material name="white"/>
    </visual>
  </link>
  <joint name="lh_LFJ5" type="revolute">
    <parent link="lh_palm"/>
    <child link="lh_lfmetacarpal"/>
    <origin rpy="-3.141592653589793 -0.6108649061631908 0.0" xyz="0.033 0.0 0.02071"/>
    <axis xyz="0.0 0.0 1.0"/>
    <!-- <origin xyz="0.033 0.0 0.02071" rpy="0.0 0.0 0.0"/> -->
    <!-- <axis xyz="0.5735761643640092 0.0 -0.819152234736298"/> -->
    <limit effort="100" lower="0.0" upper="0.785398" velocity="100"/>
  </joint>
  <link name="lh_lfknuckle">
    <visual name="f_knuckle">
      <origin rpy="0.4761390295154802 0.007276744315003247 -0.01128884895567703" xyz="-8.015943942283821e-06 0.00028383334511582203 0.0003141144870240873"/>
      <geometry>
        <mesh filename="stl/f_knuckle.stl"/>
      </geometry>
      <material name="white"/>
    </visual>
  </link>
  <joint name="lh_LFJ4" type="revolute">
    <parent link="lh_lfmetacarpal"/>
    <child link="lh_lfknuckle"/>
    <!-- <origin xyz="0.0 0.0 0.06579" rpy="0.0 0.0 0.0"/> -->
    <origin rpy="-3.141592653589793 -0.6108649061631908 0" xyz="0.03773558 0. -0.05389203"/>
    <axis xyz="0.0 -1.0 0.0"/>
    <limit effort="100" lower="-0.349066" upper="0.349066" velocity="100"/>
  </joint>
  <link name="lh_lfproximal">
    <visual name="f_proximal">
      <origin rpy="-7.135757573614219e-06 0.01189393423812235 1.5705980355726104" xyz="1.2104673000657597e-06 9.76175282387983e-06 0.022880653343431333"/>
      <geometry>
        <mesh filename="stl/f_proximal.stl"/>
      </geometry>
      <material name="white"/>
    </visual>
  </link>
  <joint name="lh_LFJ3" type="revolute">
    <parent link="lh_lfknuckle"/>
    <child link="lh_lfproximal"/>
    <origin rpy="0.0 0.0 0.0" xyz="0.0 0.0 0.0"/>
    <axis xyz="1.0 0.0 0.0"/>
    <limit effort="100" lower="-0.261799" upper="1.5708" velocity="100"/>
  </joint>
  <link name="lh_lfmiddle">
    <visual name="f_middle">
      <origin rpy="-1.5154077996843905e-05 -0.00025673504362555555 1.5707963267948966" xyz="-2.7197407046965675e-06 -3.219283283025054e-05 0.011511409944870538"/>
      <geometry>
        <mesh filename="stl/f_middle.stl"/>
      </geometry>
      <material name="white"/>
    </visual>
  </link>
  <joint name="lh_LFJ2" type="revolute">
    <parent link="lh_lfproximal"/>
    <child link="lh_lfmiddle"/>
    <origin rpy="0.0 0.0 0.0" xyz="0.0 0.0 0.045"/>
    <axis xyz="1.0 0.0 0.0"/>
    <limit effort="100" lower="0.0" upper="1.5708" velocity="100"/>
  </joint>
  <link name="lh_lfdistal">
    <visual name="f_distal_pst">
      <origin rpy="1.9593220200595154e-05 0.002689843516656243 1.582276007411751" xyz="-2.398434946392576e-05 0.00042073257364413626 0.017646475317320408"/>
      <geometry>
        <mesh filename="stl/f_distal_pst.stl"/>
      </geometry>
      <material name="white"/>
    </visual>
  </link>
  <joint name="lh_LFJ1" type="revolute">
    <parent link="lh_lfmiddle"/>
    <child link="lh_lfdistal"/>
    <origin rpy="0.0 0.0 0.0" xyz="0.0 0.0 0.025"/>
    <axis xyz="1.0 0.0 0.0"/>
    <limit effort="100" lower="0.0" upper="1.5708" velocity="100"/>
  </joint>
  <link name="lh_thbase"/>
  <joint name="lh_THJ5" type="revolute">
    <parent link="lh_palm"/>
    <child link="lh_thbase"/>
    <origin rpy="0.0 0.7853970066908715 3.141592653589793" xyz="-0.034 -0.00858 0.029"/>
    <axis xyz="0.0 0.0 1.0"/>
    <limit effort="100" lower="-1.0472" upper="1.0472" velocity="100"/>
  </joint>
  <link name="lh_thproximal">
    <visual name="th_proximal">
      <origin rpy="-4.186875454471058e-06 0.0010962409823094266 0.3847587823606159" xyz="-6.378894056540728e-06 -2.6031284627244637e-05 0.016715298411459745"/>
      <geometry>
        <mesh filename="stl/th_proximal.stl"/>
      </geometry>
      <material name="white"/>
    </visual>
  </link>
  <joint name="lh_THJ4" type="revolute">
    <parent link="lh_thbase"/>
    <child link="lh_thproximal"/>
    <origin rpy="0.0 0.0 0.0" xyz="0.0 0.0 0.0"/>
    <axis xyz="-1.0 0.0 0.0"/>
    <limit effort="100" lower="0.0" upper="1.22173" velocity="100"/>
  </joint>
  <link name="lh_thhub"/>
  <joint name="lh_THJ3" type="revolute">
    <parent link="lh_thproximal"/>
    <child link="lh_thhub"/>
    <origin rpy="0.0 0.0 0.0" xyz="0.0 0.0 0.038"/>
    <axis xyz="-1.0 0.0 0.0"/>
    <limit effort="100" lower="-0.20944" upper="0.20944" velocity="100"/>
  </joint>
  <link name="lh_thmiddle">
    <visual name="th_middle">
      <origin rpy="0.0 -0.0009035488116579948 0.0" xyz="7.479629857400793e-05 -4.506977852869377e-05 0.015348398308984388"/>
      <geometry>
        <mesh filename="stl/th_middle.stl"/>
      </geometry>
      <material name="white"/>
    </visual>
  </link>
  <joint name="lh_THJ2" type="revolute">
    <parent link="lh_thhub"/>
    <child link="lh_thmiddle"/>
    <origin rpy="0.0 0.0 0.0" xyz="0.0 0.0 0.0"/>
    <axis xyz="0.0 -1.0 0.0"/>
    <limit effort="100" lower="-0.698132" upper="0.698132" velocity="100"/>
  </joint>
  <link name="lh_thdistal">
    <visual name="th_distal_pst">
      <origin rpy="-0.0001073181947076323 0.003173495876248822 1.5706693697416252" xyz="-8.254509753145168e-07 0.000802518759472585 0.019553373143358997"/>
      <geometry>
        <mesh filename="stl/th_distal_pst.stl"/>
      </geometry>
      <material name="white"/>
    </visual>
  </link>
  <joint name="lh_THJ1" type="revolute">
    <parent link="lh_thmiddle"/>
    <child link="lh_thdistal"/>
    <origin rpy="0.0 0.0 -1.5707963267948963" xyz="0.0 0.0 0.032"/>
    <axis xyz="1.0 0.0 0.0"/>
    <limit effort="100" lower="-0.261799" upper="1.5708" velocity="100"/>
  </joint>
  <!-- <material name="white">
         <color rgba="1 1 1 1" />
      </material> -->
  <joint name="rah_joint" type="fixed">
    <origin rpy="0 0 0" xyz="0 0 0.034"/>
    <parent link="ra_RotZB"/>
    <child link="rh_palm"/>
  </joint>
  <joint name="lah_joint" type="fixed">
    <origin rpy="0 0 0" xyz="0 0 0.034"/>
    <parent link="la_RotZB"/>
    <child link="lh_palm"/>
  </joint>
  <!-- world frame -->
  <link name="world"/>
  <joint name="ra_world_joint" type="fixed">
    <origin rpy="0 0 0" xyz="0 -0.1 0"/>
    <parent link="world"/>
    <child link="ra_base"/>
  </joint>
  <joint name="la_world_joint" type="fixed">
    <origin rpy="0 0 0" xyz="0 0.1 0"/>
    <parent link="world"/>
    <child link="la_base"/>
  </joint>
</robot>
